Workbook
Name stock: 'Item List'!$B$2:$H$248
Name Category: 'Item List'!$A$2:$A$248

Sheet Form responses 4
A1: Timestamp | B1: SKU CODE | C1: ITEM NAME | D1: IMAGE
A2: 46112.621 | B2: C-COA-110 | C2: Radicure Textured Duct Matt | D2: https://drive.google.com/open?id=15OalsFpwAjmWweTsFYgxHVJwlHVUOrfW
A3: 46112.625 | B3: A-TAP-129 | C3: At 2/65 Self Adhesive Tape Brown | D3: https://drive.google.com/open?id=1eoarVdSIW-FWXvjJ5IlP87HNQeICGb7a
A4: 46112.626 | B4: A-TAP-126 | C4: At 1/65 Self Adhesive Tape Brown | D4: https://drive.google.com/open?id=1eCiRaaTGtTtap2W2KO_o_uMkF6xE5VKn
A5: 46112.626 | B5: A-TAP-130 | C5: Ft 4 Self Adhesive D/S Foam Tape 24 Mm | D5: https://drive.google.com/open?id=15lm7cnf-ZJVrn1bQo0j3P8XIX3gtbW1v
A6: 46112.627 | B6: CET-CET-131 | C6: Ceta | D6: https://drive.google.com/open?id=1z_asE2y1Wsu7Y8AhQgJDh-KtHwJrvxk7
A7: 46112.627 | B7: CH-GUM-135 | C7: Protection Gum | D7: https://drive.google.com/open?id=1l796wJNfFv_yKYCpNrSKFl7LHFAPYgXm
A8: 46112.628 | B8: CH-ADH-139 | C8: Roller Paste-Glazekeen Hydromac | D8: https://drive.google.com/open?id=1aH3j5AIBXWQspgvXJeChlmLCXHTPFZWf
A9: 46112.629 | B9: CH-VAR-141 | C9: Flash Dry Varnishing-Ultra Shield Duct Gloss | D9: https://drive.google.com/open?id=10ukvEUd_XB-JXOW9hDh_kkk1SQbhAan_
A10: 46112.629 | B10: CH-SOL-142 | C10: Plate Cleaner Normal | D10: https://drive.google.com/open?id=1DimIEAfsPMYzV23a30n75iVLHc4TkImo
A11: 46112.63 | B11: CH-SOL-143 | C11: Plate Cleaner UV | D11: https://drive.google.com/open?id=1aSPhXsfV7yWwkK7fUWyOt-4VQ1bIAbzS
A12: 46112.63 | B12: CH-SOL-144 | C12: Benzene | D12: https://drive.google.com/open?id=1cOX6jzMdMaAE0EadLM4K1zgyoi0JsG5k
A13: 46112.631 | B13: A-GLU-160 | C13: Jelly Glue | D13: https://drive.google.com/open?id=1Lx8j9w2fSDf5pzQD_wZec7hzhzoFCcc3
... A57: 46275.54 | B57: I-PAN-420 | C57: MULTANI RAJBHOGPRASH IMMUNITY SYRUP | D57: https://drive.google.com/open?id=1fg6SVnk5_QtwZcIDFyH4K_L0cbjodaJ-

Sheet Paper Batch Issues_conflict2120
A1: Issue ID | B1: Timestamp | C1: Batch ID | D1: SKU | E1: Item Name | F1: Qty Issued | G1: Job Ref | H1: Department | I1: Remark | J1: Entered By

Sheet Paper Batches
A1: Batch ID | B1: Date Received | C1: SKU | D1: Item Name | E1: Unit | F1: Qty Received | G1: Job Ref | H1: Remaining Qty | I1: Status | J1: Remark | K1: Entered By | L1: GRN ID
A2: OPEN-P-SBS-003 | B2: 46234.567 | C2: P-SBS-003 | D2: Sbs Paper 23X36 300Gsm White | E2: Sheet | F2: 400 | H2: 400 | I2: Active | J2: Opening balance — seeded from IMS closing stock | K2: system
A3: OPEN-P-SBS-005 | B3: 46234.567 | C3: P-SBS-005 | D3: Sbs Paper 23X39 325Gsm | E3: Sheet | F3: 1000 | H3: 400 | I3: Active | J3: Opening balance — seeded from IMS closing stock | K3: system
A4: OPEN-P-SBS-007 | B4: 46234.567 | C4: P-SBS-007 | D4: Sbs Paper 25X36 325Gsm Cream | E4: Sheet | F4: 800 | H4: 100 | I4: Active | J4: Opening balance — seeded from IMS closing stock | K4: system
A5: OPEN-P-SBS-009 | B5: 46234.567 | C5: P-SBS-009 | D5: Sbs Paper 31.5X41.5 350Gsm Cream | E5: Sheet | F5: 30 | H5: 30 | I5: Active | J5: Opening balance — seeded from IMS closing stock | K5: system
A6: OPEN-P-SBS-010 | B6: 46234.567 | C6: P-SBS-010 | D6: Sbs Paper 26X38 345Gsm Cream | E6: Sheet | F6: 400 | H6: 400 | I6: Active | J6: Opening balance — seeded from IMS closing stock | K6: system
A7: OPEN-P-SBS-012 | B7: 46234.567 | C7: P-SBS-012 | D7: Sbs Paper 22X32 300Gsm Cream | E7: Sheet | F7: 1000 | H7: 1000 | I7: Active | J7: Opening balance — seeded from IMS closing stock | K7: system
A8: OPEN-P-SBS-015 | B8: 46234.567 | C8: P-SBS-015 | D8: Sbs Paper 22X28 320Gsm | E8: Sheet | F8: 150 | H8: 0 | I8: Exhausted | J8: Opening balance — seeded from IMS closing stock | K8: system
A9: OPEN-P-SBS-016 | B9: 46234.567 | C9: P-SBS-016 | D9: Sbs Paper 25X30 320Gsm Cream | E9: Sheet | F9: 2000 | H9: 2000 | I9: Active | J9: Opening balance — seeded from IMS closing stock | K9: system
A10: OPEN-P-SBS-018 | B10: 46234.567 | C10: P-SBS-018 | D10: Sbs Paper 25X36 300Gsm | E10: Sheet | F10: 400 | H10: 400 | I10: Active | J10: Opening balance — seeded from IMS closing stock | K10: system
A11: OPEN-P-SBS-019 | B11: 46234.567 | C11: P-SBS-019 | D11: Sbs Paper 24X27 300Gsm White | E11: Sheet | F11: 600 | H11: 600 | I11: Active | J11: Opening balance — seeded from IMS closing stock | K11: system
A12: OPEN-P-SBS-020 | B12: 46234.567 | C12: P-SBS-020 | D12: Sbs Paper 31.5X41.5 380Gsm Cream | E12: Sheet | F12: 2600 | H12: 1000 | I12: Active | J12: Opening balance — seeded from IMS closing stock | K12: system
A13: OPEN-P-SBS-021 | B13: 46234.567 | C13: P-SBS-021 | D13: Sbs Paper 25X31 330Gsm White | E13: Sheet | F13: 600 | H13: 600 | I13: Active | J13: Opening balance — seeded from IMS closing stock | K13: system
... A253: OPEN-P-SBS-399 | B253: 46234.567 | C253: P-SBS-399 | D253: SBS 20X38 345Gsm | E253: Sheet | F253: 100 | H253: 0 | I253: Exhausted | J253: Opening balance — seeded from IMS closing stock | K253: system
A254: GRN-260803-153646-L1 | B254: 46237 | C254: P-SBS-385 | D254: Sbs Paper 22X28 290Gsm | E254: Sheet | F254: 600 | G254: DAP INNER | H254: 0 | I254: Exhausted | K254: unknown | L254: GRN-260803-153646
A255: GRN-260803-153646-L2 | B255: 46237 | C255: P-SBS-393 | D255: Sbs Paper 28X40 325Gsm | E255: Sheet | F255: 500 | G255: RED RICE | H255: 0 | I255: Exhausted | K255: unknown | L255: GRN-260803-153646
A256: GRN-260803-153646-L3 | B256: 46237 | C256: P-SBS-346 | D256: SBS Board 23X36 325Gsm | E256: Sheet | F256: 1900 | G256: 4 IN 1 PRIMER, VML | H256: 0 | I256: Exhausted | K256: unknown | L256: GRN-260803-153646
A257: GRN-260803-153646-L4 | B257: 46237 | C257: P-SBS-277 | D257: Sbs Paper 31.5X41.5 330 Gsm | E257: Sheet | F257: 500 | G257: RED RICE SYRUM | H257: 0 | I257: Exhausted | K257: unknown | L257: GRN-260803-153646
A258: GRN-260807-110449-L1 | B258: 46240 | C258: CH-SOL-116 | D258: Nova Nol Xtra | E258: Ltr | F258: 40 | H258: 0 | I258: Exhausted | K258: unknown | L258: GRN-260807-110449
A259: GRN-260807-110449-L2 | B259: 46240 | C259: C-COA-110 | D259: Radicure Textured Duct Matt | E259: Kg | F259: 1 | H259: 0 | I259: Exhausted | K259: unknown | L259: GRN-260807-110449
A260: CORR-260807-110756 | B260: 46241.464 | C260: CH-VAR-141 | D260: Ultra Shield 417 Duct Gloss OP Varnish | E260: Kg | F260: 20 | H260: 20 | I260: Active | J260: Stock Count Correction — physical count found 20 more than system | K260: unknown
A261: GRN-260807-130931-L1 | B261: 46241 | C261: C-COA-110 | D261: Radicure Textured Duct Matt | E261: Kg | F261: 2 | H261: 0 | I261: Exhausted | K261: unknown | L261: GRN-260807-130931
A262: GRN-260807-131011-L1 | B262: 46241 | C262: CH-SOL-144 | D262: Benzene | E262: Ltr | F262: 20 | H262: 0 | I262: Exhausted | K262: unknown | L262: GRN-260807-131011
A263: GRN-260814-133526-L1 | B263: 46247 | C263: P-SBS-004 | D263: Sbs Paper 23X39 350Gsm | E263: Sheet | F263: 3600 | G263: FERRO NAUTRAL | H263: 0 | I263: Exhausted | K263: unknown | L263: GRN-260814-133526
A264: GRN-260814-133526-L2 | B264: 46247 | C264: P-SBS-326 | D264: Sbs Paper 22X32 325Gsm | E264: Sheet | F264: 4100 | G264: LTP OUTER, SAUCER 5PACKET | H264: 0 | I264: Exhausted | K264: unknown | L264: GRN-260814-133526
A265: GRN-260814-133526-L3 | B265: 46247 | C265: P-SBS-296 | D265: Sbs Paper 25X30 330Gsm | E265: Sheet | F265: 1000 | G265: LONG STAY | H265: 0 | I265: Exhausted | K265: unknown | L265: GRN-260814-133526
A266: GRN-260814-133835-L1 | B266: 46247 | C266: P-SBS-400 | D266: Sbs Paper 28X40 290Gsm | E266: Sheet | F266: 600 | G266: JOB HR GOLD, PAPAYA | H266: 0 | I266: Exhausted | K266: unknown | L266: GRN-260814-133835
A267: GRN-260814-133835-L2 | B267: 46247 | C267: P-SBS-310 | D267: sbs 23X36 350Gsm | E267: Sheet | F267: 1000 | G267: KAPIVA | H267: 0 | I267: Exhausted | K267: unknown | L267: GRN-260814-133835
A268: GRN-260814-134220-L1 | B268: 46246 | C268: P-SBS-007 | D268: Sbs Paper 25X36 325Gsm Cream | E268: Sheet | F268: 2200 | G268: CCP | H268: 0 | I268: Exhausted | K268: unknown | L268: GRN-260814-134220
A269: GRN-260814-134220-L2 | B269: 46246 | C269: P-SBS-230 | D269: Sbs Paper 28X40 350Gsm | E269: Sheet | F269: 1000 | G269: ENERVIVE | H269: 0 | I269: Exhausted | K269: unknown | L269: GRN-260814-134220
A270: GRN-260814-135007-L1 | B270: 46245 | C270: P-DUP-192 | D270: Duplex 31.5X41.5 300Gsm White Back | E270: Sheet | F270: 648 | G270: 3PIN 6AMP | H270: 0 | I270: Exhausted | K270: unknown | L270: GRN-260814-135007
A271: GRN-260814-135007-L2 | B271: 46245 | C271: P-DUP-055 | D271: Duplex 23X36 300Gsm Gray Back | E271: Sheet | F271: 2592 | G271: SKY ENGINE VALVES OUTER | H271: 0 | I271: Exhausted | K271: unknown | L271: GRN-260814-135007
A272: GRN-260814-135007-L3 | B272: 46245 | C272: P-DUP-995 | D272: Duplex 31.5x41.5 250Gsm Gray Back | E272: Sheet | F272: 720 | G272: 7W MARVAL | H272: 720 | I272: Active | K272: unknown | L272: GRN-260814-135007
A273: GRN-260814-135007-L4 | B273: 46245 | C273: P-DUP-355 | D273: Duplex 22X32 300Gsm Gray Back | E273: Sheet | F273: 864 | G273: 13W MARVEL | H273: 0 | I273: Exhausted | K273: unknown | L273: GRN-260814-135007
A274: GRN-260814-135530-L1 | B274: 46248 | C274: P-SBS-037 | D274: Sbs Paper 21X36 325Gsm Cream | E274: Sheet | F274: 600 | G274: SILKVEIL | H274: 0 | I274: Exhausted | K274: unknown | L274: GRN-260814-135530
... A291: GRN-260820-182215-L1 | B291: 46254 | C291: P-SBS-407 | D291: SPECIAL PAPER 23X35.8 300GSM | E291: Sheet | F291: 1200 | G291: Multani - outlet PS card | H291: 0 | I291: Exhausted | K291: unknown | L291: GRN-260820-182215
A292: GRN-260820-182551-L1 | B292: 46254 | C292: I-CMY-226 | D292: Radicure Led 100000 PRO WHITE | E292: Kg | F292: 4 | H292: 2 | I292: Active | K292: unknown | L292: GRN-260820-182551
A293: CORR-260820-182625 | B293: 46254.768 | C293: C-COA-110 | D293: Radicure Textured Duct Matt | E293: Kg | F293: 7 | H293: 0 | I293: Exhausted | J293: Stock Count Correction — physical count found 7 more than system | K293: unknown
A294: CORR-260820-182657 | B294: 46254.769 | C294: I-CMY-225 | D294: Radicure Led 100000 PRO YELLOW | E294: Kg | F294: 4 | H294: 4 | I294: Active | J294: Stock Count Correction — physical count found 4 more than system | K294: unknown
A295: CORR-260820-182758 | B295: 46254.769 | C295: I-CMY-229 | D295: Radicure Led 100000 PRO BLACK | E295: Kg | F295: 5 | H295: 5 | I295: Active | J295: Stock Count Correction — physical count found 5 more than system | K295: unknown
...

Sheet Paper Batch Issues
A1: Issue ID | B1: Timestamp | C1: Batch ID | D1: SKU | E1: Item Name | F1: Qty Issued | G1: Job Ref | H1: Department | I1: Remark | J1: Entered By
A2: I-260806-112725-0 | B2: 46240.477 | C2: OPEN-CH-SOL-116 | D2: CH-SOL-116 | E2: Nova Nol Xtra | F2: 20 | H2: Offset Printing | J2: unknown
A3: I-260807-131121-0 | B3: 46241.55 | C3: GRN-260807-110449-L2 | D3: C-COA-110 | E3: Radicure Textured Duct Matt | F3: 1 | H3: Post-Press / Finishing | I3: NEW MATERIAL TESTING | J3: unknown
A4: I-260807-131121-1 | B4: 46241.55 | C4: GRN-260807-130931-L1 | D4: C-COA-110 | E4: Radicure Textured Duct Matt | F4: 1 | H4: Post-Press / Finishing | I4: NEW MATERIAL TESTING | J4: unknown
A5: I-260807-132102-0 | B5: 46241.556 | C5: OPEN-I-PAN-273 | D5: I-PAN-273 | E5: Inkstylo pan 271C | F5: 2 | H5: Offset Printing | I5: JOB CLOUD KISS | J5: unknown
A6: I-260807-145250-0 | B6: 46241.62 | C6: OPEN-P-SBS-399 | D6: P-SBS-399 | E6: SBS 20X38 345Gsm | F6: 100 | H6: Pre-Press | J6: unknown
A7: I-260820-170231-0 | B7: 46254.71 | C7: GRN-260820-145704-L1 | D7: P-SBS-330 | E7: Sbs Paper 25X30 325Gsm Cream | F7: 1000 | G7: LONG STAY | H7: Post-Press / Finishing | I7: CLEAR- | J7: unknown
A8: I-260820-170315-0 | B8: 46254.711 | C8: GRN-260803-153646-L1 | D8: P-SBS-385 | E8: Sbs Paper 22X28 290Gsm | F8: 600 | G8: DAP INNER | H8: Offset Printing | J8: unknown
A9: I-260820-170409-0 | B9: 46254.711 | C9: GRN-260803-153646-L3 | D9: P-SBS-346 | E9: SBS Board 23X36 325Gsm | F9: 1900 | G9: 4 IN 1 PRIMER, VML | H9: Offset Printing | J9: unknown
A10: I-260820-171506-0 | B10: 46254.719 | C10: GRN-260803-153646-L2 | D10: P-SBS-393 | E10: Sbs Paper 28X40 325Gsm | F10: 500 | G10: RED RICE | H10: Offset Printing | I10: 500 | J10: unknown
A11: I-260820-171510-0 | B11: 46254.719 | C11: GRN-260803-153646-L4 | D11: P-SBS-277 | E11: Sbs Paper 31.5X41.5 330 Gsm | F11: 500 | G11: RED RICE SYRUM | H11: Offset Printing | J11: unknown
A12: I-260820-171514-0 | B12: 46254.719 | C12: GRN-260814-140908-L1 | D12: P-SBS-037 | E12: Sbs Paper 21X36 325Gsm Cream | F12: 1400 | G12: TONER AND CLOUD KISS | H12: Offset Printing | I12: 4 PKT TONER, 10 PKT CLOUD KISS | J12: unknown
A13: I-260820-171519-0 | B13: 46254.719 | C13: GRN-260814-140908-L2 | D13: P-SBS-007 | E13: Sbs Paper 25X36 325Gsm Cream | F13: 400 | G13: HYDRASHINE | H13: Offset Printing | J13: unknown
A14: I-260820-171524-0 | B14: 46254.719 | C14: GRN-260814-140908-L3 | D14: P-SBS-326 | E14: Sbs Paper 22X32 325Gsm | F14: 1400 | G14: PRIMER GEL | H14: Offset Printing | I14: 1400 | J14: unknown
A15: I-260820-171528-0 | B15: 46254.719 | C15: GRN-260814-140908-L4 | D15: P-SBS-393 | E15: Sbs Paper 28X40 325Gsm | F15: 1200 | G15: GLOW EDIT AND PORE REFINER GOLD | H15: Offset Printing | I15: 4PKT 8PKT | J15: unknown
A16: I-260820-171532-0 | B16: 46254.719 | C16: GRN-260814-140243-L1 | D16: P-SBS-191 | E16: SBS 23X36 345Gsm | F16: 1100 | G16: WHITE-GRIP AND STYLE | H16: Offset Printing | I16: 1100 | J16: unknown
A17: I-260820-171536-0 | B17: 46254.719 | C17: GRN-260814-140243-L2 | D17: P-SBS-230 | E17: Sbs Paper 28X40 350Gsm | F17: 1200 | G17: OJB BB CREAM | H17: Offset Printing | I17: 12PKT AND 4 PKT OLD PAPER | J17: unknown
A18: I-260820-171540-0 | B18: 46254.719 | C18: GRN-260814-140243-L3 | D18: P-SBS-007 | E18: Sbs Paper 25X36 325Gsm Cream | F18: 1000 | G18: FOTTY NOTTY | H18: Offset Printing | J18: unknown
A19: I-260820-171544-0 | B19: 46254.719 | C19: GRN-260814-140243-L5 | D19: P-SBS-352 | E19: SBS 22x32 290Gsm | F19: 3000 | G19: HAIR TOUCH UP | H19: Offset Printing | I19: 3000 | J19: unknown
A20: I-260820-171548-0 | B20: 46254.719 | C20: GRN-260814-135007-L1 | D20: P-DUP-192 | E20: Duplex 31.5X41.5 300Gsm White Back | F20: 648 | G20: 3PIN 6AMP | H20: Offset Printing | J20: unknown
A21: I-260820-171552-0 | B21: 46254.719 | C21: GRN-260814-135007-L2 | D21: P-DUP-055 | E21: Duplex 23X36 300Gsm Gray Back | F21: 2592 | G21: SKY ENGINE VALVES OUTER | H21: Offset Printing | J21: unknown
A22: I-260820-171556-0 | B22: 46254.719 | C22: GRN-260814-135007-L4 | D22: P-DUP-355 | E22: Duplex 22X32 300Gsm Gray Back | F22: 864 | G22: 13W MARVEL | H22: Offset Printing | J22: unknown
A23: I-260820-171601-0 | B23: 46254.719 | C23: GRN-260814-134220-L1 | D23: P-SBS-007 | E23: Sbs Paper 25X36 325Gsm Cream | F23: 2200 | G23: CCP | H23: Offset Printing | J23: unknown
A24: I-260820-171606-0 | B24: 46254.72 | C24: GRN-260814-133526-L1 | D24: P-SBS-004 | E24: Sbs Paper 23X39 350Gsm | F24: 3600 | G24: FERRO NAUTRAL | H24: Offset Printing | J24: unknown
A25: I-260820-171610-0 | B25: 46254.72 | C25: GRN-260814-133526-L2 | D25: P-SBS-326 | E25: Sbs Paper 22X32 325Gsm | F25: 4100 | G25: LTP OUTER, SAUCER 5PACKET | H25: Offset Printing | J25: unknown
A26: I-260820-171614-0 | B26: 46254.72 | C26: GRN-260814-133526-L3 | D26: P-SBS-296 | E26: Sbs Paper 25X30 330Gsm | F26: 1000 | G26: LONG STAY | H26: Offset Printing | J26: unknown
A27: I-260820-171618-0 | B27: 46254.72 | C27: GRN-260814-133835-L1 | D27: P-SBS-400 | E27: Sbs Paper 28X40 290Gsm | F27: 600 | G27: JOB HR GOLD, PAPAYA | H27: Offset Printing | J27: unknown
A28: I-260820-171623-0 | B28: 46254.72 | C28: GRN-260814-135530-L1 | D28: P-SBS-037 | E28: Sbs Paper 21X36 325Gsm Cream | F28: 600 | G28: SILKVEIL | H28: Offset Printing | J28: unknown
A29: I-260820-171627-0 | B29: 46254.72 | C29: GRN-260814-135530-L2 | D29: P-SBS-393 | E29: Sbs Paper 28X40 325Gsm | F29: 700 | G29: SPF | H29: Offset Printing | J29: unknown
A30: I-260820-171635-0 | B30: 46254.72 | C30: GRN-260814-135530-L3 | D30: P-SBS-326 | E30: Sbs Paper 22X32 325Gsm | F30: 800 | G30: HD FOUNDATION | H30: Offset Printing | J30: unknown
A31: I-260820-171639-0 | B31: 46254.72 | C31: GRN-260814-135530-L5 | D31: P-SBS-296 | E31: Sbs Paper 25X30 330Gsm | F31: 1000 | G31: 8W SCREW | H31: Offset Printing | J31: unknown
A32: I-260820-171956-0 | B32: 46254.722 | C32: GRN-260814-135530-L4 | D32: P-SBS-346 | E32: SBS Board 23X36 325Gsm | F32: 600 | G32: SAUCER, SPACE SHIP AND STAR | H32: Offset Printing | J32: unknown
A33: I-260821-131047-0 | B33: 46255.549 | C33: OPEN-I-CMY-228 | D33: I-CMY-228 | E33: Radicure Led 100000 PRO CYAN | F33: 1 | H33: Offset Printing | J33: unknown
A34: I-260821-131108-0 | B34: 46255.549 | C34: OPEN-I-CMY-225 | D34: I-CMY-225 | E34: Radicure Led 100000 PRO YELLOW | F34: 1 | H34: Offset Printing | J34: unknown
A35: I-260821-131145-0 | B35: 46255.55 | C35: GRN-260807-130931-L1 | D35: C-COA-110 | E35: Radicure Textured Duct Matt | F35: 1 | H35: Post-Press / Finishing | J35: unknown
A36: I-260821-131145-1 | B36: 46255.55 | C36: CORR-260820-182625 | D36: C-COA-110 | E36: Radicure Textured Duct Matt | F36: 1 | H36: Post-Press / Finishing | J36: unknown
A37: I-260822-101638-0 | B37: 46256.428 | C37: CORR-260820-182625 | D37: C-COA-110 | E37: Radicure Textured Duct Matt | F37: 2 | H37: Post-Press / Finishing | I37: hybrid uv- | J37: unknown
A38: I-260825-154240-0 | B38: 46259.655 | C38: OPEN-M-DHO-165 | D38: M-DHO-165 | E38: Dhoti | F38: 15 | H38: Offset Printing | J38: unknown
A39: I-260825-183145-0 | B39: 46259.772 | C39: GRN-260814-133835-L2 | D39: P-SBS-310 | E39: sbs 23X36 350Gsm | F39: 1000 | G39: KAPIVA | H39: Offset Printing | J39: unknown
A40: I-260825-183150-0 | B40: 46259.772 | C40: GRN-260820-150132-L1 | D40: P-SBS-406 | E40: SBS 20X38 325GSM CREAM | F40: 1400 | G40: EFFLAIR | H40: Offset Printing | I40: 11pkt and 3 pkt | J40: unknown
...

Sheet Stock Adjustments
A1: Adjustment ID | B1: Timestamp | C1: Batch ID | D1: SKU | E1: Item Name | F1: Qty Adjusted | G1: Reason | H1: Remark | I1: Entered By
A2: ADJ-260806-114718-0 | B2: 46240.491 | C2: OPEN-CH-SOL-144 | D2: CH-SOL-144 | E2: Benzene | F2: -10 | G2: Count Correction | H2: PHYSICAL CHECK | I2: unknown
A3: ADJ-260807-110528-0 | B3: 46241.462 | C3: OPEN-C-COA-110 | D3: C-COA-110 | E3: Radicure Textured Duct Matt | F3: -4 | G3: Count Correction | I3: unknown
A4: ADJ-260807-110756 | B4: 46241.464 | C4: CORR-260807-110756 | D4: CH-VAR-141 | E4: Ultra Shield 417 Duct Gloss OP Varnish | F4: 20 | G4: Count Correction | I4: unknown
A5: ADJ-260820-182625 | B5: 46254.768 | C5: CORR-260820-182625 | D5: C-COA-110 | E5: Radicure Textured Duct Matt | F5: 7 | G5: Count Correction | H5: UPDATE | I5: unknown
A6: ADJ-260820-182657 | B6: 46254.769 | C6: CORR-260820-182657 | D6: I-CMY-225 | E6: Radicure Led 100000 PRO YELLOW | F6: 4 | G6: Count Correction | H6: UPDATE | I6: unknown
A7: ADJ-260820-182729-0 | B7: 46254.769 | C7: OPEN-I-CMY-226 | D7: I-CMY-226 | E7: Radicure Led 100000 PRO WHITE | F7: -5 | G7: Count Correction | I7: unknown
A8: ADJ-260820-182758 | B8: 46254.769 | C8: CORR-260820-182758 | D8: I-CMY-229 | E8: Radicure Led 100000 PRO BLACK | F8: 5 | G8: Count Correction | H8: UPDATE | I8: unknown
A9: ADJ-260820-182823 | B9: 46254.77 | C9: CORR-260820-182823 | D9: I-CMY-228 | E9: Radicure Led 100000 PRO CYAN | F9: 5 | G9: Count Correction | I9: unknown
A10: ADJ-260820-183025 | B10: 46254.771 | C10: CORR-260820-183025 | D10: I-CMY-227 | E10: Radicure Led 100000 PRO MAGENTA | F10: 2 | G10: Count Correction | I10: unknown
A11: ADJ-260820-183340-0 | B11: 46254.773 | C11: OPEN-I-CMY-071 | D11: I-CMY-071 | E11: Sicura Smartcure Uv - Led Pr Magenta | F11: -3 | G11: Count Correction | I11: unknown
A12: ADJ-260820-183355-0 | B12: 46254.774 | C12: OPEN-I-CMY-072 | D12: I-CMY-072 | E12: Sicura Smartcure Uv - Led Pr Yellow | F12: -2 | G12: Count Correction | I12: unknown
A13: ADJ-260820-183420-0 | B13: 46254.774 | C13: OPEN-I-CMY-073 | D13: I-CMY-073 | E13: Sicura Smartcure Uv - Led Pr Black | F13: -2 | G13: Count Correction | I13: unknown
A14: ADJ-260822-101722-0 | B14: 46256.429 | C14: OPEN-M-DHO-165 | D14: M-DHO-165 | E14: Dhoti | F14: -1084 | G14: Count Correction | H14: big adjustment | I14: unknown
A15: ADJ-260822-101755-0 | B15: 46256.429 | C15: GRN-260807-110449-L1 | D15: CH-SOL-116 | E15: Nova Nol Xtra | F15: -40 | G15: Count Correction | I15: unknown
A16: ADJ-260824-164145-0 | B16: 46258.696 | C16: OPEN-CH-SOL-268 | D16: CH-SOL-268 | E16: Screen Clearning Aid Amyle | F16: -5 | G16: Count Correction | I16: unknown
A17: ADJ-260901-135711-0 | B17: 46266.581 | C17: CORR-260820-182625 | D17: C-COA-110 | E17: Radicure Textured Duct Matt | F17: -1 | G17: Count Correction | I17: unknown
A18: ADJ-260901-135711-1 | B18: 46266.581 | C18: GRN-260824-161141-L2 | D18: C-COA-110 | E18: Radicure Textured Duct Matt | F18: -4 | G18: Count Correction | I18: unknown
A19: ADJ-260901-135711-2 | B19: 46266.581 | C19: GRN-260901-134301-L1 | D19: C-COA-110 | E19: Radicure Textured Duct Matt | F19: -1 | G19: Count Correction | I19: unknown
A20: ADJ-260901-141226-0 | B20: 46266.592 | C20: OPEN-CH-SOL-199 | D20: CH-SOL-199 | E20: TK 3400 Wb Board Primer | F20: -25 | G20: Count Correction | I20: unknown
A21: ADJ-260901-155208-0 | B21: 46266.661 | C21: OPEN-P-SBS-337 | D21: P-SBS-337 | E21: SBS PAPER 34.5X40 325Gsm | F21: -2500 | G21: Count Correction | I21: unknown
A22: ADJ-260902-130044 | B22: 46267.542 | C22: OPEN-I-CMY-061 | D22: I-CMY-061 | E22: Universal Plus Black Ink | F22: -6 | G22: Count Correction | I22: unknown
A23: ADJ-260902-130125 | B23: 46267.543 | C23: OPEN-I-CMY-064 | D23: I-CMY-064 | E23: Universal Plus Yellow | F23: -4 | G23: Count Correction | I23: unknown
A24: ADJ-260902-131618 | B24: 46267.553 | C24: OPEN-I-CMY-063 | D24: I-CMY-063 | E24: Universal Plus Magenta | F24: -8 | G24: Count Correction | I24: unknown
A25: ADJ-260902-131741 | B25: 46267.554 | C25: OPEN-I-CMY-062 | D25: I-CMY-062 | E25: Universal Plus Cyan Ink | F25: -6 | G25: Count Correction | I25: unknown
A26: ADJ-260902-132311 | B26: 46267.558 | C26: OPEN-I-CMY-225 | D26: I-CMY-225 | E26: Radicure Led 100000 PRO YELLOW | F26: 1 | G26: Count Correction | I26: unknown
... A52: ADJ-260905-183751-0 | B52: 46270.776 | C52: OPEN-I-PAN-083 | D52: I-PAN-083 | E52: Pan 021c | F52: -5 | G52: Count Correction | I52: unknown

Sheet GRN
A1: GRN ID | B1: Date | C1: Vendor | D1: Invoice/Challan No | E1: Invoice Image | F1: Remark | G1: Entered By
A2: GRN-260803-153646 | B2: 46237 | C2: M/s SUGANDH ENTERPRISES | D2: 3158 | E2: https://drive.google.com/file/d/1POaWVoFiZUo9FDkq_UDQjmDGl2v7hHy6/view?usp=drivesdk | G2: unknown
A3: GRN-260807-110449 | B3: 46240 | C3: DS INDIA | D3: INV01 | G3: unknown
A4: GRN-260807-130931 | B4: 46241 | C4: DS INDIA | D4: OK26/3254 | G4: unknown
A5: GRN-260807-131011 | B5: 46241 | C5: DS INDIA | D5: OK26/3255 | G5: unknown
A6: GRN-260814-133526 | B6: 46247 | C6: SUGANDH ENTERPRISES | D6: 386 | E6: https://drive.google.com/file/d/1jiWlkvuJ7EJaCczbhXkth89NRmdx2xS1/view?usp=drivesdk | G6: unknown
A7: GRN-260814-133835 | B7: 46247 | C7: SUGANDHA | D7: 3401 | E7: https://drive.google.com/file/d/1mCM2rCWosn2aZM-8dOlZwFLg-OXFz41t/view?usp=drivesdk | G7: unknown
A8: GRN-260814-134220 | B8: 46246 | C8: SUGANDH ENTERPRISES | D8: 3394 | E8: https://drive.google.com/file/d/16T5SZl-w2AIoW7qfTHIq3sNfXQfNZPfH/view?usp=drivesdk | G8: unknown
A9: GRN-260814-135007 | B9: 46245 | C9: VT | D9: 4387 | E9: https://drive.google.com/file/d/10TvKtelbyXaDDO3YwT309grxo_-t7XNc/view?usp=drivesdk | G9: unknown
A10: GRN-260814-135530 | B10: 46248 | C10: SUGANDH ENTERPRISES | D10: 3358 | E10: https://drive.google.com/file/d/1fdNxdmeGbCej4VAGDAeq52vro_cf6wuH/view?usp=drivesdk | G10: unknown
A11: GRN-260814-140243 | B11: 46242 | C11: SUGANDH ENTERPRISES | D11: 3293 | E11: https://drive.google.com/file/d/1jqJF1dO7v8y1E2xfs3ZS-IykpY5rXyrc/view?usp=drivesdk | G11: unknown
A12: GRN-260814-140908 | B12: 46239 | C12: SUGANDH ENTERPRISES | D12: 3213 | E12: https://drive.google.com/file/d/1LW3oHLE70UVplYTKWk5s4WeQLSYasdi_/view?usp=drivesdk | G12: unknown
A13: GRN-260820-145704 | B13: 46248 | C13: SUGANDH ENTERPRISES | D13: 3457 | E13: https://drive.google.com/file/d/14RdYNG_MEWCeiP0yib1mhv0rvjeh5eLz/view?usp=drivesdk | G13: unknown
A14: GRN-260820-150132 | B14: 46253 | C14: SUGANDH ENTERPRISES | D14: 3514 | E14: https://drive.google.com/file/d/1rPD7BlyBT_LF1D13zCb0eM-RryixopT8/view?usp=drivesdk | G14: unknown
A15: GRN-260820-182215 | B15: 46254 | C15: ANIL AGENCIES PVT LTD | D15: AAPL/3238/26-27 | E15: https://drive.google.com/file/d/1okiSon3jNL3DwU2InmCGXNEonJ_rFY5T/view?usp=drivesdk | G15: unknown
A16: GRN-260820-182551 | B16: 46254 | C16: JAIN ARORA | D16: ---- | G16: unknown
A17: GRN-260820-190621 | B17: 46254 | C17: SUGANDH ENTERPRISES | D17: 3572 | E17: https://drive.google.com/file/d/1A0abbVBnkJ5R2BzaaEMZu_XCKIkeW34f/view?usp=drivesdk | G17: unknown
A18: GRN-260820-190757 | B18: 46254 | C18: SUGANDH ENTERPRISES | D18: 3570 | E18: https://drive.google.com/file/d/1AG1J3Z19fsksfpL--J-1JZA7qktne5RM/view?usp=drivesdk | G18: unknown
A19: GRN-260824-161141 | B19: 46258 | C19: DSD INDIA | D19: INV26272408 | G19: unknown
A20: GRN-260825-154328 | B20: 46258 | C20: SHYAM LAL DHOTI | D20: INV111 | G20: unknown
A21: GRN-260825-183711 | B21: 46255 | C21: VT | D21: 4217 | E21: https://drive.google.com/file/d/1uuVr3MNLrmjablmddaGgRKf-waH-UNLJ/view?usp=drivesdk | G21: unknown
A22: GRN-260825-193128 | B22: 46258 | C22: D D ENTERPRISES | D22: 4842 | E22: https://drive.google.com/file/d/1z-fAn2MJeUdtrWTQlj4RI73Vam8ysfpz/view?usp=drivesdk | G22: unknown
A23: GRN-260826-153644 | B23: 46251 | C23: DS INDIA | D23: 1111 | E23: https://drive.google.com/file/d/1k3GVllCUCwVnnhBSD33kfVHPeFMgLgp_/view?usp=drivesdk | G23: unknown
A24: GRN-260827-135001 | B24: 46260 | C24: SUGANDH ENTERPRISES | D24: 3702 | E24: https://drive.google.com/file/d/1vKs43bvx6SamW87uR8bA5iOmxyfCZcvn/view?usp=drivesdk | G24: unknown
A25: GRN-260827-135231 | B25: 46260 | C25: SUGANDH ENTERPRISES | D25: 3699 | E25: https://drive.google.com/file/d/17MZWZBoa69AXsHEqhBmnJVmBySDJmDay/view?usp=drivesdk | G25: unknown
A26: GRN-260827-135410 | B26: 46260 | C26: VT | D26: 1142 | G26: unknown
A27: GRN-260827-135604 | B27: 46259 | C27: Shri Mahavir Papers Trading Pvt Ltd | D27: 4902/OK | E27: https://drive.google.com/file/d/1yDYRN1xEy4Lt1W0ULzY14CB-nyHqlqi2/view?usp=drivesdk | G27: unknown
A28: GRN-260827-135758 | B28: 46259 | C28: SUGANDH ENTERPRISES | D28: 3643 | E28: https://drive.google.com/file/d/1TCzVaeIzb5EiGEkPpI8Bbfg-Rf4Ipkiw/view?usp=drivesdk | G28: unknown
A29: GRN-260827-140051 | B29: 46261 | C29: Shri Mahavir Papers Trading Pvt Ltd | D29: 4897/OK | E29: https://drive.google.com/file/d/1U9JqmYAL_FPQtoPvVF5rmwzTo3d-ED_r/view?usp=drivesdk | G29: unknown
A30: GRN-260831-155325 | B30: 46265 | C30: SUNEJA SONS | D30: 26-27/1373 | E30: https://drive.google.com/file/d/1gaZCQsjryedsdzFsK1ac-cwhOxRCD4MW/view?usp=drivesdk | G30: unknown
A31: GRN-260901-134301 | B31: 46266 | C31: D.S.INDIA | D31: OK26/3902 | E31: https://drive.google.com/file/d/1rjO9-avp37eVAaDnCq4aap1iqK5MwyWY/view?usp=drivesdk | G31: unknown
A32: GRN-260901-140314 | B32: 46265 | C32: VT | D32: 4237 | E32: https://drive.google.com/file/d/1auxuwDL0BYUifGTyE6Bd8dX8CZX2rkuk/view?usp=drivesdk | G32: unknown
A33: GRN-260901-143739 | B33: 46266 | C33: SUGANDH ENTERPRISES | D33: 3811 | E33: https://drive.google.com/file/d/1pTHudKD3vM-AQxqrvyRIuzHpOe9B1O5a/view?usp=drivesdk | G33: unknown
A34: GRN-260901-154957 | B34: 46265 | C34: SUGANDH ENTERPRISES | D34: 3794 | E34: https://drive.google.com/file/d/1ToUkxk6hfNQKOpIW9bIyxD0h0QTCXc-X/view?usp=drivesdk | G34: unknown
A35: GRN-260902-163557 | B35: 46255 | C35: EVEREST PAPER CONVERTOR | D35: EPC-197/26-27 | E35: https://drive.google.com/file/d/1KVYJhVVdFowESKB7xSJUy2ZJya1wOX_Y/view?usp=drivesdk | G35: unknown
A36: GRN-260902-182546 | B36: 46267 | C36: DHARMKOT | D36: 50 | E36: https://drive.google.com/file/d/1e2pv0nfJe0WjcWKVup55NktQqnSYeZwt/view?usp=drivesdk | G36: unknown
A37: GRN-260902-182853 | B37: 46267 | C37: SUDARSHAN PAPER COMPANY | D37: 29699 | E37: https://drive.google.com/file/d/1mdcXHBd9nh8HbXbQ0P7lLUbH5PcdGL5j/view?usp=drivesdk | G37: unknown
A38: GRN-260905-154042 | B38: 46269 | C38: SUĞANDH ENTERPRISES | D38: 3872 | E38: https://drive.google.com/file/d/1ZRhIzn-gxvDMXZS_WSkuj_H7RxLdaLNV/view?usp=drivesdk | G38: unknown
A39: GRN-260905-172741 | B39: 46270 | C39: ds india | D39: ok26-27 | G39: unknown
A40: GRN-260905-173106 | B40: 46270 | C40: SHYAMLAL | D40: ---- | G40: unknown
...

Sheet Item Record Check
A1: Item Record Checker | B1: Category | C1: Material | D1: Size | E1: Gsm/Mic | F1: Color | G1: Finish/Extra
B2: Paper | D2: 20X32
A6: =IFERROR(__xludf.DUMMYFUNCTION("IFERROR( QUERY( 'Item List'!A:I, ""select I, A, B, C, D, E, F, G, H where 1=1"" & IF(B2<>"""","" and B = '""&B2&""'"","""") & IF(C2<>"""","" and C = '""&C2&""'"","""") & IF(D2<>"""","" and D = '""&D2&""'"","""") & IF(E2<>"""","" "&"and E = '""&E2&""'"","""") & IF(F2<>"""","" and F = '""&F2&""'"","""") & IF(G2<>"""","" and G = '""&G2&""'"","""") ,1), ""❌ No matching record found"" )"),"SKU CODE") -> SKU CODE | B6: =IFERROR(__xludf.DUMMYFUNCTION("""COMPUTED_VALUE"""),"Item Name ") -> Item Name | C6: =IFERROR(__xludf.DUMMYFUNCTION("""COMPUTED_VALUE"""),"Category") -> Category | D6: =IFERROR(__xludf.DUMMYFUNCTION("""COMPUTED_VALUE"""),"Material") -> Material | E6: =IFERROR(__xludf.DUMMYFUNCTION("""COMPUTED_VALUE"""),"Size") -> Size | F6: =IFERROR(__xludf.DUMMYFUNCTION("""COMPUTED_VALUE"""),"Gsm/Mic") -> Gsm/Mic | G6: =IFERROR(__xludf.DUMMYFUNCTION("""COMPUTED_VALUE"""),"Color") -> Color | H6: =IFERROR(__xludf.DUMMYFUNCTION("""COMPUTED_VALUE"""),"Finish/Extra") -> Finish/Extra | I6: =IFERROR(__xludf.DUMMYFUNCTION("""COMPUTED_VALUE"""),"Unit") -> Unit | J6: Stock
A7: =IFERROR(__xludf.DUMMYFUNCTION("""COMPUTED_VALUE"""),"P-SBS-417") -> P-SBS-417 | B7: =IFERROR(__xludf.DUMMYFUNCTION("""COMPUTED_VALUE"""),"20X32") -> 20X32 | C7: =IFERROR(__xludf.DUMMYFUNCTION("""COMPUTED_VALUE"""),"Paper") -> Paper | D7: =IFERROR(__xludf.DUMMYFUNCTION("""COMPUTED_VALUE"""),"Sbs Paper") -> Sbs Paper | E7: =IFERROR(__xludf.DUMMYFUNCTION("""COMPUTED_VALUE"""),"20X32") -> 20X32 | F7: =IFERROR(__xludf.DUMMYFUNCTION("""COMPUTED_VALUE"""),"330Gsm") -> 330Gsm | G7: =IFERROR(__xludf.DUMMYFUNCTION("""COMPUTED_VALUE"""),"–") -> – | H7: =IFERROR(__xludf.DUMMYFUNCTION("""COMPUTED_VALUE"""),"–") -> – | I7: =IFERROR(__xludf.DUMMYFUNCTION("""COMPUTED_VALUE"""),"Sheet") -> Sheet | J7: {=if(A7:A1000<>"",VLOOKUP(A7:A1000,IMS!$A$2:$E$999,5,0),"")} -> 0

Sheet InOut (Manual)
A1: Timestamp | B1: SKU CODE | C1: In/Out | D1: Date | E1: Quantity | F1: Department | G1: Remark | H1: Job Name | I1: Item Name | J1: Category | K1: Material | L1: Size | M1: Gsm/Mic | N1: Color | O1: Finish/Extra | P1: Unit | Q1: Closing Stock
A2: 46053.76 | B2: P-SBS-001 | C2: In | D2: 46050 | E2: 2300 | F2: Cutting | I2: {=BYROW( B2:B3074, LAMBDA(sku, IF( sku="","", _xlfn.XLOOKUP( sku, 'Item List'!I:I, 'Item List'!A:H, "" ) ) ) )} -> Sbs Paper 23X36 330Gsm White | J2: Paper | K2: Sbs Paper | L2: 23X36 | M2: 330Gsm | N2: White | O2: – | P2: Sheet | Q2: {=if(B2:B3074<>"",VLOOKUP(B2:B3074,IMS!$A$2:$E$999,5,0),"")} -> 0
A3: 46053.76 | B3: P-SBS-002 | C3: In | D3: 46050 | E3: 1000 | F3: Cutting | I3: Sbs Paper 23X36 330Gsm Cream | J3: Paper | K3: Sbs Paper | L3: 23X36 | M3: 330Gsm | N3: Cream | O3: – | P3: Sheet | Q3: 0
A4: 46053.76 | B4: P-SBS-003 | C4: In | D4: 46050 | E4: 3300 | F4: Cutting | I4: Sbs Paper 23X36 300Gsm White | J4: Paper | K4: Sbs Paper | L4: 23X36 | M4: 300Gsm | N4: White | O4: – | P4: Sheet | Q4: 400
A5: 46053.76 | B5: P-SBS-004 | C5: In | D5: 46050 | E5: 500 | F5: Cutting | I5: Sbs Paper 23X39 350Gsm | J5: Paper | K5: Sbs Paper | L5: 23X39 | M5: 350Gsm | N5: – | O5: – | P5: Sheet | Q5: 600
A6: 46053.76 | B6: P-SBS-005 | C6: In | D6: 46050 | E6: 300 | F6: Cutting | I6: Sbs Paper 23X39 325Gsm | J6: Paper | K6: Sbs Paper | L6: 23X39 | M6: 325Gsm | N6: – | O6: – | P6: Sheet | Q6: 2600
A7: 46053.76 | B7: P-SBS-006 | C7: In | D7: 46050 | E7: 1100 | F7: Cutting | I7: Sbs Paper 23X36 300Gsm Cream | J7: Paper | K7: Sbs Paper | L7: 23X36 | M7: 300Gsm | N7: Cream | O7: – | P7: Sheet | Q7: 800
A8: 46053.76 | B8: P-SBS-007 | C8: In | D8: 46050 | E8: 1700 | F8: Cutting | I8: Sbs Paper 25X36 325Gsm Cream | J8: Paper | K8: Sbs Paper | L8: 25X36 | M8: 325Gsm | N8: Cream | O8: – | P8: Sheet | Q8: 200
A9: 46053.76 | B9: P-SBS-008 | C9: In | D9: 46050 | E9: 150 | F9: Cutting | I9: Sbs Paper 25X36 325Gsm White | J9: Paper | K9: Sbs Paper | L9: 25X36 | M9: 325Gsm | N9: White | O9: – | P9: Sheet | Q9: 0
A10: 46053.76 | B10: P-SBS-009 | C10: In | D10: 46050 | E10: 1200 | F10: Cutting | I10: Sbs Paper 31.5X41.5 350Gsm Cream | J10: Paper | K10: Sbs Paper | L10: 31.5X41.5 | M10: 350Gsm | N10: Cream | O10: – | P10: Sheet | Q10: 30
A11: 46053.76 | B11: P-SBS-010 | C11: In | D11: 46050 | E11: 1400 | F11: Cutting | I11: Sbs Paper 26X38 345Gsm Cream | J11: Paper | K11: Sbs Paper | L11: 26X38 | M11: 345Gsm | N11: Cream | O11: – | P11: Sheet | Q11: 400
A12: 46053.76 | B12: P-SBS-011 | C12: In | D12: 46050 | E12: 1500 | F12: Cutting | I12: Sbs Paper 22X32 330Gsm Cream | J12: Paper | K12: Sbs Paper | L12: 22X32 | M12: 330Gsm | N12: Cream | O12: – | P12: Sheet | Q12: 0
A13: 46053.76 | B13: P-SBS-012 | C13: In | D13: 46050 | E13: 600 | F13: Cutting | I13: Sbs Paper 22X32 300Gsm Cream | J13: Paper | K13: Sbs Paper | L13: 22X32 | M13: 300Gsm | N13: Cream | O13: – | P13: Sheet | Q13: 1000
A14: 46053.76 | B14: P-SBS-013 | C14: In | D14: 46050 | E14: 5400 | F14: Cutting | I14: Sbs Paper 22X28 330Gsm White | J14: Paper | K14: Sbs Paper | L14: 22X28 | M14: 330Gsm | N14: White | O14: – | P14: Sheet | Q14: 1800
... A173: 46053.771 | B173: C-FOI-172 | C173: In | D173: 46052 | E173: 3 | F173: Store | I173: Led Pr cyan led process | J173: Coating | K173: Foil | L173: – | M173: – | N173: – | O173: Led-Exc26013v | P173: Kg | Q173: 3
A174: 46053.771 | B174: M-DHO-165 | C174: Out | D174: 46052 | E174: 5 | I174: Dhoti | J174: Miscellaneous | K174: Dhoti | L174: – | M174: – | N174: – | O174: – | P174: Pc | Q174: 580
A175: 46053.771 | B175: A-TAP-120 | C175: Out | D175: 46052 | E175: 1 | I175: Self Adhesive Tissue Tape 10 Mm | J175: Adhesive | K175: Tape | L175: 10Mm | M175: – | N175: – | O175: – | P175: Pc | Q175: 6
A176: 46053.771 | B176: M-DHO-165 | C176: Out | D176: 46053 | E176: 10 | F176: Printing | I176: Dhoti | J176: Miscellaneous | K176: Dhoti | L176: – | M176: – | N176: – | O176: – | P176: Pc | Q176: 580
A177: 46053.771 | B177: M-DHO-165 | C177: Out | D177: 46053 | E177: 10 | F177: Die Cutting | I177: Dhoti | J177: Miscellaneous | K177: Dhoti | L177: – | M177: – | N177: – | O177: – | P177: Pc | Q177: 580
A178: 46053.771 | B178: CH-SOL-118 | C178: Out | D178: 46053 | E178: 1 | F178: Printing | I178: Anti Set off spray | J178: Chemical | K178: Solution | L178: – | M178: – | N178: – | O178: – | P178: Pkt | Q178: 3
A179: 46053.771 | B179: P-SBS-017 | C179: Out | D179: 46052 | E179: 2500 | F179: Cutting | I179: Sbs Paper 21X36 340Gsm Cream | J179: Paper | K179: Sbs Paper | L179: 21X36 | M179: 340Gsm | N179: Cream | O179: – | P179: Sheet | Q179: 0
A180: 46053.771 | B180: P-SBS-004 | C180: Out | D180: 46052 | E180: 500 | F180: Cutting | I180: Sbs Paper 23X39 350Gsm | J180: Paper | K180: Sbs Paper | L180: 23X39 | M180: 350Gsm | N180: – | O180: – | P180: Sheet | Q180: 600
A181: 46053.771 | B181: P-SBS-015 | C181: Out | D181: 46052 | E181: 700 | F181: Cutting | I181: Sbs Paper 22X28 320Gsm | J181: Paper | K181: Sbs Paper | L181: 22X28 | M181: 320Gsm | N181: – | O181: – | P181: Sheet | Q181: 0
A182: 46053.771 | B182: P-SBS-173 | C182: In | D182: 46052 | E182: 3300 | F182: Cutting | I182: Sbs Paper 25X30 300Gsm Cream | J182: Paper | K182: Sbs Paper | L182: 25X30 | M182: 300Gsm | N182: Cream | O182: – | P182: Sheet | Q182: 400
A183: 46024.399 | B183: P-KRA-174 | C183: In | D183: 46052 | E183: 5600 | F183: Cutting | I183: Kraft Paper 23X32 320Gsm White | J183: Paper | K183: Kraft Paper | L183: 23X32 | M183: 320Gsm | N183: White | O183: – | P183: Sheet | Q183: 35
A184: 46024.399 | B184: P-SBS-175 | C184: In | D184: 46052 | E184: 1500 | F184: Cutting | I184: Sbs Paper 28X40 330Gsm Cream | J184: Paper | K184: Sbs Paper | L184: 28X40 | M184: 330Gsm | N184: Cream | O184: – | P184: Sheet | Q184: 0
A185: 46024.399 | B185: P-ART-176 | C185: In | D185: 46053 | E185: 200 | F185: Cutting | I185: Art Card 25X36 300Gsm | J185: Paper | K185: Art Card | L185: 25X36 | M185: 300Gsm | N185: – | O185: – | P185: Sheet | Q185: 0
A186: 46024.399 | B186: P-ART-177 | C186: In | D186: 46053 | E186: 700 | F186: Cutting | I186: Art Card 20X30 250Gsm | J186: Paper | K186: Art Card | L186: 20X30 | M186: 250Gsm | N186: – | O186: – | P186: Sheet | Q186: 0
A187: 46024.399 | B187: P-ART-043 | C187: Out | D187: 46053 | E187: 130 | F187: Cutting | G187: Adjustment | I187: Art Paper 25X36 150Gsm | J187: Paper | K187: Art Paper | L187: 25X36 | M187: 150Gsm | N187: – | O187: – | P187: Sheet | Q187: 0
A188: 46024.399 | B188: P-ART-176 | C188: Out | D188: 46055 | E188: 200 | F188: Cutting | I188: Art Card 25X36 300Gsm | J188: Paper | K188: Art Card | L188: 25X36 | M188: 300Gsm | N188: – | O188: – | P188: Sheet | Q188: 0
A189: 46024.399 | B189: P-ART-177 | C189: Out | D189: 46055 | E189: 700 | F189: Cutting | I189: Art Card 20X30 250Gsm | J189: Paper | K189: Art Card | L189: 20X30 | M189: 250Gsm | N189: – | O189: – | P189: Sheet | Q189: 0
A190: 46024.399 | B190: I-CMY-064 | C190: Out | D190: 46055 | E190: 2 | F190: Printing | I190: Universal Plus Yellow | J190: Ink | K190: Cmyk | L190: – | M190: – | N190: Yellow | O190: Offset | P190: Kg | Q190: 6
A191: 46024.399 | B191: CH-SOL-144 | C191: Out | D191: 46055 | E191: 5 | F191: printing | I191: Benzene | J191: Chemical | K191: Solution | L191: – | M191: – | N191: – | O191: Chemical | P191: Ltr | Q191: 15
A192: 46024.399 | B192: P-MAP-178 | C192: In | D192: 46055 | E192: 1000 | F192: Printing | I192: Mapletho 23X36 78Gsm | J192: Paper | K192: Mapletho | L192: 23X36 | M192: 78Gsm | N192: – | O192: – | P192: Sheet | Q192: 0
A193: 46024.399 | B193: P-MAP-178 | C193: Out | D193: 46055 | E193: 850 | F193: Printing | I193: Mapletho 23X36 78Gsm | J193: Paper | K193: Mapletho | L193: 23X36 | M193: 78Gsm | N193: – | O193: – | P193: Sheet | Q193: 0
A194: 46024.399 | B194: CH-SOL-114 | C194: Out | D194: 46055 | E194: 25 | F194: Printing | I194: Classic Multi Wash-HPC 0214/25D21 | J194: Chemical | K194: Solution | L194: – | M194: – | N194: – | O194: Normal Wash | P194: Ltr | Q194: 20
A195: 46024.399 | B195: CH-SOL-179 | C195: In | D195: 46055 | E195: 25 | F195: Store | I195: New V FD Wash(Hard Wash)-HPC-0237/25D21 | J195: Chemical | K195: Solution | L195: – | M195: – | N195: – | O195: Hard Wash | P195: Ltr | Q195: 25
A196: 46024.399 | B196: M-DHO-165 | C196: Out | D196: 46055 | E196: 5 | F196: Spot Uv | I196: Dhoti | J196: Miscellaneous | K196: Dhoti | L196: – | M196: – | N196: – | O196: – | P196: Pc | Q196: 580
A197: 46024.399 | B197: P-ART-038 | C197: Out | D197: 46053 | E197: 400 | F197: Cutting | I197: Art Card 23X36 350Gsm | J197: Paper | K197: Art Card | L197: 23X36 | M197: 350Gsm | N197: – | O197: – | P197: Sheet | Q197: 0
A198: 46024.441 | B198: P-ART-046 | C198: Out | D198: 46053 | E198: 200 | F198: Cutting | I198: Art Card 23X36 300Gsm | J198: Paper | K198: Art Card | L198: 23X36 | M198: 300Gsm | N198: – | O198: – | P198: Sheet | Q198: 0
...

Sheet Sheet30

Sheet Stock Image
A1: =IFERROR(__xludf.DUMMYFUNCTION("QUERY('Item List'!A:J, ""SELECT A, B, I WHERE B != 'Paper' LABEL A 'Item Name', B 'Category', I 'SKU Code'"", 1)"),"Item Name") -> Item Name | B1: =IFERROR(__xludf.DUMMYFUNCTION("""COMPUTED_VALUE"""),"Category") -> Category | C1: =IFERROR(__xludf.DUMMYFUNCTION("""COMPUTED_VALUE"""),"SKU Code") -> SKU Code | D1: Image | E1: Sku Stock
A2: =IFERROR(__xludf.DUMMYFUNCTION("""COMPUTED_VALUE"""),"Universal Plus Black Ink") -> Universal Plus Black Ink | B2: =IFERROR(__xludf.DUMMYFUNCTION("""COMPUTED_VALUE"""),"Ink") -> Ink | C2: =IFERROR(__xludf.DUMMYFUNCTION("""COMPUTED_VALUE"""),"I-CMY-061") -> I-CMY-061 | D2: =IF(COUNTIF('Form responses 4'!B:B,C2)>0, "", "https://docs.google.com/forms/d/e/1FAIpQLSdhNamFeglgVtt555M7xM7e8ZAg9KCWMEcDlLzX1oeZsyGxrg/viewform?usp=pp_url&entry.580385001="&C2&"&entry.1376952895="&A2) | E2: =IFERROR(IF(C2<>"",VLOOKUP(C2,IMS!$A$2:$E1000,5,0),""),"") -> 16
A3: =IFERROR(__xludf.DUMMYFUNCTION("""COMPUTED_VALUE"""),"Universal Plus Cyan Ink") -> Universal Plus Cyan Ink | B3: =IFERROR(__xludf.DUMMYFUNCTION("""COMPUTED_VALUE"""),"Ink") -> Ink | C3: =IFERROR(__xludf.DUMMYFUNCTION("""COMPUTED_VALUE"""),"I-CMY-062") -> I-CMY-062 | D3: =IF(COUNTIF('Form responses 4'!B:B,C3)>0, "", "https://docs.google.com/forms/d/e/1FAIpQLSdhNamFeglgVtt555M7xM7e8ZAg9KCWMEcDlLzX1oeZsyGxrg/viewform?usp=pp_url&entry.580385001="&C3&"&entry.1376952895="&A3) | E3: =IFERROR(IF(C3<>"",VLOOKUP(C3,IMS!$A$2:$E1000,5,0),""),"") -> 10
A4: =IFERROR(__xludf.DUMMYFUNCTION("""COMPUTED_VALUE"""),"Universal Plus Magenta") -> Universal Plus Magenta | B4: =IFERROR(__xludf.DUMMYFUNCTION("""COMPUTED_VALUE"""),"Ink") -> Ink | C4: =IFERROR(__xludf.DUMMYFUNCTION("""COMPUTED_VALUE"""),"I-CMY-063") -> I-CMY-063 | D4: =IF(COUNTIF('Form responses 4'!B:B,C4)>0, "", "https://docs.google.com/forms/d/e/1FAIpQLSdhNamFeglgVtt555M7xM7e8ZAg9KCWMEcDlLzX1oeZsyGxrg/viewform?usp=pp_url&entry.580385001="&C4&"&entry.1376952895="&A4) | E4: =IFERROR(IF(C4<>"",VLOOKUP(C4,IMS!$A$2:$E1000,5,0),""),"") -> 10
A5: =IFERROR(__xludf.DUMMYFUNCTION("""COMPUTED_VALUE"""),"Universal Plus Yellow") -> Universal Plus Yellow | B5: =IFERROR(__xludf.DUMMYFUNCTION("""COMPUTED_VALUE"""),"Ink") -> Ink | C5: =IFERROR(__xludf.DUMMYFUNCTION("""COMPUTED_VALUE"""),"I-CMY-064") -> I-CMY-064 | D5: =IF(COUNTIF('Form responses 4'!B:B,C5)>0, "", "https://docs.google.com/forms/d/e/1FAIpQLSdhNamFeglgVtt555M7xM7e8ZAg9KCWMEcDlLzX1oeZsyGxrg/viewform?usp=pp_url&entry.580385001="&C5&"&entry.1376952895="&A5) | E5: =IFERROR(IF(C5<>"",VLOOKUP(C5,IMS!$A$2:$E1000,5,0),""),"") -> 6
A6: =IFERROR(__xludf.DUMMYFUNCTION("""COMPUTED_VALUE"""),"InstaCure 501 Flashdry Led Pr Black") -> InstaCure 501 Flashdry Led Pr Black | B6: =IFERROR(__xludf.DUMMYFUNCTION("""COMPUTED_VALUE"""),"Ink") -> Ink | C6: =IFERROR(__xludf.DUMMYFUNCTION("""COMPUTED_VALUE"""),"I-CMY-065") -> I-CMY-065 | D6: =IF(COUNTIF('Form responses 4'!B:B,C6)>0, "", "https://docs.google.com/forms/d/e/1FAIpQLSdhNamFeglgVtt555M7xM7e8ZAg9KCWMEcDlLzX1oeZsyGxrg/viewform?usp=pp_url&entry.580385001="&C6&"&entry.1376952895="&A6) -> https://docs.google.com/forms/d/e/1FAIpQLSdhNamFeglgVtt555M7xM7e8ZAg9KCWMEcDlLzX1oeZsyGxrg/viewform?usp=pp_url&entry.580385001=I-CMY-065&entry.1376952895=InstaCure 501 Flashdry Led Pr Black | E6: =IFERROR(IF(C6<>"",VLOOKUP(C6,IMS!$A$2:$E1000,5,0),""),"") -> 0
A7: =IFERROR(__xludf.DUMMYFUNCTION("""COMPUTED_VALUE"""),"InstaCure 501 Flashdry Led Pr White") -> InstaCure 501 Flashdry Led Pr White | B7: =IFERROR(__xludf.DUMMYFUNCTION("""COMPUTED_VALUE"""),"Ink") -> Ink | C7: =IFERROR(__xludf.DUMMYFUNCTION("""COMPUTED_VALUE"""),"I-CMY-066") -> I-CMY-066 | D7: =IF(COUNTIF('Form responses 4'!B:B,C7)>0, "", "https://docs.google.com/forms/d/e/1FAIpQLSdhNamFeglgVtt555M7xM7e8ZAg9KCWMEcDlLzX1oeZsyGxrg/viewform?usp=pp_url&entry.580385001="&C7&"&entry.1376952895="&A7) -> https://docs.google.com/forms/d/e/1FAIpQLSdhNamFeglgVtt555M7xM7e8ZAg9KCWMEcDlLzX1oeZsyGxrg/viewform?usp=pp_url&entry.580385001=I-CMY-066&entry.1376952895=InstaCure 501 Flashdry Led Pr White | E7: =IFERROR(IF(C7<>"",VLOOKUP(C7,IMS!$A$2:$E1000,5,0),""),"") -> 0
A8: =IFERROR(__xludf.DUMMYFUNCTION("""COMPUTED_VALUE"""),"InstaCure 501 Flashdry Led Pr Magenta") -> InstaCure 501 Flashdry Led Pr Magenta | B8: =IFERROR(__xludf.DUMMYFUNCTION("""COMPUTED_VALUE"""),"Ink") -> Ink | C8: =IFERROR(__xludf.DUMMYFUNCTION("""COMPUTED_VALUE"""),"I-CMY-067") -> I-CMY-067 | D8: =IF(COUNTIF('Form responses 4'!B:B,C8)>0, "", "https://docs.google.com/forms/d/e/1FAIpQLSdhNamFeglgVtt555M7xM7e8ZAg9KCWMEcDlLzX1oeZsyGxrg/viewform?usp=pp_url&entry.580385001="&C8&"&entry.1376952895="&A8) -> https://docs.google.com/forms/d/e/1FAIpQLSdhNamFeglgVtt555M7xM7e8ZAg9KCWMEcDlLzX1oeZsyGxrg/viewform?usp=pp_url&entry.580385001=I-CMY-067&entry.1376952895=InstaCure 501 Flashdry Led Pr Magenta | E8: =IFERROR(IF(C8<>"",VLOOKUP(C8,IMS!$A$2:$E1000,5,0),""),"") -> 1
A9: =IFERROR(__xludf.DUMMYFUNCTION("""COMPUTED_VALUE"""),"InstaCure 501 Flashdry Led Pr Yellow") -> InstaCure 501 Flashdry Led Pr Yellow | B9: =IFERROR(__xludf.DUMMYFUNCTION("""COMPUTED_VALUE"""),"Ink") -> Ink | C9: =IFERROR(__xludf.DUMMYFUNCTION("""COMPUTED_VALUE"""),"I-CMY-068") -> I-CMY-068 | D9: =IF(COUNTIF('Form responses 4'!B:B,C9)>0, "", "https://docs.google.com/forms/d/e/1FAIpQLSdhNamFeglgVtt555M7xM7e8ZAg9KCWMEcDlLzX1oeZsyGxrg/viewform?usp=pp_url&entry.580385001="&C9&"&entry.1376952895="&A9) -> https://docs.google.com/forms/d/e/1FAIpQLSdhNamFeglgVtt555M7xM7e8ZAg9KCWMEcDlLzX1oeZsyGxrg/viewform?usp=pp_url&entry.580385001=I-CMY-068&entry.1376952895=InstaCure 501 Flashdry Led Pr Yellow | E9: =IFERROR(IF(C9<>"",VLOOKUP(C9,IMS!$A$2:$E1000,5,0),""),"") -> 1
A10: =IFERROR(__xludf.DUMMYFUNCTION("""COMPUTED_VALUE"""),"InstaCure 501 Flashdry Led - Pr Cyan") -> InstaCure 501 Flashdry Led - Pr Cyan | B10: =IFERROR(__xludf.DUMMYFUNCTION("""COMPUTED_VALUE"""),"Ink") -> Ink | C10: =IFERROR(__xludf.DUMMYFUNCTION("""COMPUTED_VALUE"""),"I-CMY-069") -> I-CMY-069 | D10: =IF(COUNTIF('Form responses 4'!B:B,C10)>0, "", "https://docs.google.com/forms/d/e/1FAIpQLSdhNamFeglgVtt555M7xM7e8ZAg9KCWMEcDlLzX1oeZsyGxrg/viewform?usp=pp_url&entry.580385001="&C10&"&entry.1376952895="&A10) -> https://docs.google.com/forms/d/e/1FAIpQLSdhNamFeglgVtt555M7xM7e8ZAg9KCWMEcDlLzX1oeZsyGxrg/viewform?usp=pp_url&entry.580385001=I-CMY-069&entry.1376952895=InstaCure 501 Flashdry Led - Pr Cyan | E10: =IFERROR(IF(C10<>"",VLOOKUP(C10,IMS!$A$2:$E1000,5,0),""),"") -> 1
A11: =IFERROR(__xludf.DUMMYFUNCTION("""COMPUTED_VALUE"""),"Sicura Smartcure Uv - Led Pr Cyan") -> Sicura Smartcure Uv - Led Pr Cyan | B11: =IFERROR(__xludf.DUMMYFUNCTION("""COMPUTED_VALUE"""),"Ink") -> Ink | C11: =IFERROR(__xludf.DUMMYFUNCTION("""COMPUTED_VALUE"""),"I-CMY-070") -> I-CMY-070 | D11: =IF(COUNTIF('Form responses 4'!B:B,C11)>0, "", "https://docs.google.com/forms/d/e/1FAIpQLSdhNamFeglgVtt555M7xM7e8ZAg9KCWMEcDlLzX1oeZsyGxrg/viewform?usp=pp_url&entry.580385001="&C11&"&entry.1376952895="&A11) -> https://docs.google.com/forms/d/e/1FAIpQLSdhNamFeglgVtt555M7xM7e8ZAg9KCWMEcDlLzX1oeZsyGxrg/viewform?usp=pp_url&entry.580385001=I-CMY-070&entry.1376952895=Sicura Smartcure Uv - Led Pr Cyan | E11: =IFERROR(IF(C11<>"",VLOOKUP(C11,IMS!$A$2:$E1000,5,0),""),"") -> 3
A12: =IFERROR(__xludf.DUMMYFUNCTION("""COMPUTED_VALUE"""),"Sicura Smartcure Uv - Led Pr Magenta") -> Sicura Smartcure Uv - Led Pr Magenta | B12: =IFERROR(__xludf.DUMMYFUNCTION("""COMPUTED_VALUE"""),"Ink") -> Ink | C12: =IFERROR(__xludf.DUMMYFUNCTION("""COMPUTED_VALUE"""),"I-CMY-071") -> I-CMY-071 | D12: =IF(COUNTIF('Form responses 4'!B:B,C12)>0, "", "https://docs.google.com/forms/d/e/1FAIpQLSdhNamFeglgVtt555M7xM7e8ZAg9KCWMEcDlLzX1oeZsyGxrg/viewform?usp=pp_url&entry.580385001="&C12&"&entry.1376952895="&A12) -> https://docs.google.com/forms/d/e/1FAIpQLSdhNamFeglgVtt555M7xM7e8ZAg9KCWMEcDlLzX1oeZsyGxrg/viewform?usp=pp_url&entry.580385001=I-CMY-071&entry.1376952895=Sicura Smartcure Uv - Led Pr Magenta | E12: =IFERROR(IF(C12<>"",VLOOKUP(C12,IMS!$A$2:$E1000,5,0),""),"") -> 0
A13: =IFERROR(__xludf.DUMMYFUNCTION("""COMPUTED_VALUE"""),"Sicura Smartcure Uv - Led Pr Yellow") -> Sicura Smartcure Uv - Led Pr Yellow | B13: =IFERROR(__xludf.DUMMYFUNCTION("""COMPUTED_VALUE"""),"Ink") -> Ink | C13: =IFERROR(__xludf.DUMMYFUNCTION("""COMPUTED_VALUE"""),"I-CMY-072") -> I-CMY-072 | D13: =IF(COUNTIF('Form responses 4'!B:B,C13)>0, "", "https://docs.google.com/forms/d/e/1FAIpQLSdhNamFeglgVtt555M7xM7e8ZAg9KCWMEcDlLzX1oeZsyGxrg/viewform?usp=pp_url&entry.580385001="&C13&"&entry.1376952895="&A13) -> https://docs.google.com/forms/d/e/1FAIpQLSdhNamFeglgVtt555M7xM7e8ZAg9KCWMEcDlLzX1oeZsyGxrg/viewform?usp=pp_url&entry.580385001=I-CMY-072&entry.1376952895=Sicura Smartcure Uv - Led Pr Yellow | E13: =IFERROR(IF(C13<>"",VLOOKUP(C13,IMS!$A$2:$E1000,5,0),""),"") -> 0
A14: =IFERROR(__xludf.DUMMYFUNCTION("""COMPUTED_VALUE"""),"Sicura Smartcure Uv - Led Pr Black") -> Sicura Smartcure Uv - Led Pr Black | B14: =IFERROR(__xludf.DUMMYFUNCTION("""COMPUTED_VALUE"""),"Ink") -> Ink | C14: =IFERROR(__xludf.DUMMYFUNCTION("""COMPUTED_VALUE"""),"I-CMY-073") -> I-CMY-073 | D14: =IF(COUNTIF('Form responses 4'!B:B,C14)>0, "", "https://docs.google.com/forms/d/e/1FAIpQLSdhNamFeglgVtt555M7xM7e8ZAg9KCWMEcDlLzX1oeZsyGxrg/viewform?usp=pp_url&entry.580385001="&C14&"&entry.1376952895="&A14) -> https://docs.google.com/forms/d/e/1FAIpQLSdhNamFeglgVtt555M7xM7e8ZAg9KCWMEcDlLzX1oeZsyGxrg/viewform?usp=pp_url&entry.580385001=I-CMY-073&entry.1376952895=Sicura Smartcure Uv - Led Pr Black | E14: =IFERROR(IF(C14<>"",VLOOKUP(C14,IMS!$A$2:$E1000,5,0),""),"") -> 0
A15: =IFERROR(__xludf.DUMMYFUNCTION("""COMPUTED_VALUE"""),"Pan 520c") -> Pan 520c | B15: =IFERROR(__xludf.DUMMYFUNCTION("""COMPUTED_VALUE"""),"Ink") -> Ink | C15: =IFERROR(__xludf.DUMMYFUNCTION("""COMPUTED_VALUE"""),"I-PAN-074") -> I-PAN-074 | D15: =IF(COUNTIF('Form responses 4'!B:B,C15)>0, "", "https://docs.google.com/forms/d/e/1FAIpQLSdhNamFeglgVtt555M7xM7e8ZAg9KCWMEcDlLzX1oeZsyGxrg/viewform?usp=pp_url&entry.580385001="&C15&"&entry.1376952895="&A15) -> https://docs.google.com/forms/d/e/1FAIpQLSdhNamFeglgVtt555M7xM7e8ZAg9KCWMEcDlLzX1oeZsyGxrg/viewform?usp=pp_url&entry.580385001=I-PAN-074&entry.1376952895=Pan 520c | E15: =IFERROR(IF(C15<>"",VLOOKUP(C15,IMS!$A$2:$E1000,5,0),""),"") -> 2
A16: =IFERROR(__xludf.DUMMYFUNCTION("""COMPUTED_VALUE"""),"Pan 1777c") -> Pan 1777c | B16: =IFERROR(__xludf.DUMMYFUNCTION("""COMPUTED_VALUE"""),"Ink") -> Ink | C16: =IFERROR(__xludf.DUMMYFUNCTION("""COMPUTED_VALUE"""),"I-PAN-075") -> I-PAN-075 | D16: =IF(COUNTIF('Form responses 4'!B:B,C16)>0, "", "https://docs.google.com/forms/d/e/1FAIpQLSdhNamFeglgVtt555M7xM7e8ZAg9KCWMEcDlLzX1oeZsyGxrg/viewform?usp=pp_url&entry.580385001="&C16&"&entry.1376952895="&A16) -> https://docs.google.com/forms/d/e/1FAIpQLSdhNamFeglgVtt555M7xM7e8ZAg9KCWMEcDlLzX1oeZsyGxrg/viewform?usp=pp_url&entry.580385001=I-PAN-075&entry.1376952895=Pan 1777c | E16: =IFERROR(IF(C16<>"",VLOOKUP(C16,IMS!$A$2:$E1000,5,0),""),"") -> 1
A17: =IFERROR(__xludf.DUMMYFUNCTION("""COMPUTED_VALUE"""),"Pan 295c") -> Pan 295c | B17: =IFERROR(__xludf.DUMMYFUNCTION("""COMPUTED_VALUE"""),"Ink") -> Ink | C17: =IFERROR(__xludf.DUMMYFUNCTION("""COMPUTED_VALUE"""),"I-PAN-076") -> I-PAN-076 | D17: =IF(COUNTIF('Form responses 4'!B:B,C17)>0, "", "https://docs.google.com/forms/d/e/1FAIpQLSdhNamFeglgVtt555M7xM7e8ZAg9KCWMEcDlLzX1oeZsyGxrg/viewform?usp=pp_url&entry.580385001="&C17&"&entry.1376952895="&A17) -> https://docs.google.com/forms/d/e/1FAIpQLSdhNamFeglgVtt555M7xM7e8ZAg9KCWMEcDlLzX1oeZsyGxrg/viewform?usp=pp_url&entry.580385001=I-PAN-076&entry.1376952895=Pan 295c | E17: =IFERROR(IF(C17<>"",VLOOKUP(C17,IMS!$A$2:$E1000,5,0),""),"") -> 8
A18: =IFERROR(__xludf.DUMMYFUNCTION("""COMPUTED_VALUE"""),"Pan 429c") -> Pan 429c | B18: =IFERROR(__xludf.DUMMYFUNCTION("""COMPUTED_VALUE"""),"Ink") -> Ink | C18: =IFERROR(__xludf.DUMMYFUNCTION("""COMPUTED_VALUE"""),"I-PAN-077") -> I-PAN-077 | D18: =IF(COUNTIF('Form responses 4'!B:B,C18)>0, "", "https://docs.google.com/forms/d/e/1FAIpQLSdhNamFeglgVtt555M7xM7e8ZAg9KCWMEcDlLzX1oeZsyGxrg/viewform?usp=pp_url&entry.580385001="&C18&"&entry.1376952895="&A18) -> https://docs.google.com/forms/d/e/1FAIpQLSdhNamFeglgVtt555M7xM7e8ZAg9KCWMEcDlLzX1oeZsyGxrg/viewform?usp=pp_url&entry.580385001=I-PAN-077&entry.1376952895=Pan 429c | E18: =IFERROR(IF(C18<>"",VLOOKUP(C18,IMS!$A$2:$E1000,5,0),""),"") -> 1
A19: =IFERROR(__xludf.DUMMYFUNCTION("""COMPUTED_VALUE"""),"Pan 326c") -> Pan 326c | B19: =IFERROR(__xludf.DUMMYFUNCTION("""COMPUTED_VALUE"""),"Ink") -> Ink | C19: =IFERROR(__xludf.DUMMYFUNCTION("""COMPUTED_VALUE"""),"I-PAN-078") -> I-PAN-078 | D19: =IF(COUNTIF('Form responses 4'!B:B,C19)>0, "", "https://docs.google.com/forms/d/e/1FAIpQLSdhNamFeglgVtt555M7xM7e8ZAg9KCWMEcDlLzX1oeZsyGxrg/viewform?usp=pp_url&entry.580385001="&C19&"&entry.1376952895="&A19) -> https://docs.google.com/forms/d/e/1FAIpQLSdhNamFeglgVtt555M7xM7e8ZAg9KCWMEcDlLzX1oeZsyGxrg/viewform?usp=pp_url&entry.580385001=I-PAN-078&entry.1376952895=Pan 326c | E19: =IFERROR(IF(C19<>"",VLOOKUP(C19,IMS!$A$2:$E1000,5,0),""),"") -> 1
A20: =IFERROR(__xludf.DUMMYFUNCTION("""COMPUTED_VALUE"""),"Pan 7505c") -> Pan 7505c | B20: =IFERROR(__xludf.DUMMYFUNCTION("""COMPUTED_VALUE"""),"Ink") -> Ink | C20: =IFERROR(__xludf.DUMMYFUNCTION("""COMPUTED_VALUE"""),"I-PAN-079") -> I-PAN-079 | D20: =IF(COUNTIF('Form responses 4'!B:B,C20)>0, "", "https://docs.google.com/forms/d/e/1FAIpQLSdhNamFeglgVtt555M7xM7e8ZAg9KCWMEcDlLzX1oeZsyGxrg/viewform?usp=pp_url&entry.580385001="&C20&"&entry.1376952895="&A20) -> https://docs.google.com/forms/d/e/1FAIpQLSdhNamFeglgVtt555M7xM7e8ZAg9KCWMEcDlLzX1oeZsyGxrg/viewform?usp=pp_url&entry.580385001=I-PAN-079&entry.1376952895=Pan 7505c | E20: =IFERROR(IF(C20<>"",VLOOKUP(C20,IMS!$A$2:$E1000,5,0),""),"") -> 1
A21: =IFERROR(__xludf.DUMMYFUNCTION("""COMPUTED_VALUE"""),"Pan 185c") -> Pan 185c | B21: =IFERROR(__xludf.DUMMYFUNCTION("""COMPUTED_VALUE"""),"Ink") -> Ink | C21: =IFERROR(__xludf.DUMMYFUNCTION("""COMPUTED_VALUE"""),"I-PAN-080") -> I-PAN-080 | D21: =IF(COUNTIF('Form responses 4'!B:B,C21)>0, "", "https://docs.google.com/forms/d/e/1FAIpQLSdhNamFeglgVtt555M7xM7e8ZAg9KCWMEcDlLzX1oeZsyGxrg/viewform?usp=pp_url&entry.580385001="&C21&"&entry.1376952895="&A21) -> https://docs.google.com/forms/d/e/1FAIpQLSdhNamFeglgVtt555M7xM7e8ZAg9KCWMEcDlLzX1oeZsyGxrg/viewform?usp=pp_url&entry.580385001=I-PAN-080&entry.1376952895=Pan 185c | E21: =IFERROR(IF(C21<>"",VLOOKUP(C21,IMS!$A$2:$E1000,5,0),""),"") -> 2
A22: =IFERROR(__xludf.DUMMYFUNCTION("""COMPUTED_VALUE"""),"Pan 377c") -> Pan 377c | B22: =IFERROR(__xludf.DUMMYFUNCTION("""COMPUTED_VALUE"""),"Ink") -> Ink | C22: =IFERROR(__xludf.DUMMYFUNCTION("""COMPUTED_VALUE"""),"I-PAN-081") -> I-PAN-081 | D22: =IF(COUNTIF('Form responses 4'!B:B,C22)>0, "", "https://docs.google.com/forms/d/e/1FAIpQLSdhNamFeglgVtt555M7xM7e8ZAg9KCWMEcDlLzX1oeZsyGxrg/viewform?usp=pp_url&entry.580385001="&C22&"&entry.1376952895="&A22) -> https://docs.google.com/forms/d/e/1FAIpQLSdhNamFeglgVtt555M7xM7e8ZAg9KCWMEcDlLzX1oeZsyGxrg/viewform?usp=pp_url&entry.580385001=I-PAN-081&entry.1376952895=Pan 377c | E22: =IFERROR(IF(C22<>"",VLOOKUP(C22,IMS!$A$2:$E1000,5,0),""),"") -> 2
A23: =IFERROR(__xludf.DUMMYFUNCTION("""COMPUTED_VALUE"""),"Pan 3125c") -> Pan 3125c | B23: =IFERROR(__xludf.DUMMYFUNCTION("""COMPUTED_VALUE"""),"Ink") -> Ink | C23: =IFERROR(__xludf.DUMMYFUNCTION("""COMPUTED_VALUE"""),"I-PAN-082") -> I-PAN-082 | D23: =IF(COUNTIF('Form responses 4'!B:B,C23)>0, "", "https://docs.google.com/forms/d/e/1FAIpQLSdhNamFeglgVtt555M7xM7e8ZAg9KCWMEcDlLzX1oeZsyGxrg/viewform?usp=pp_url&entry.580385001="&C23&"&entry.1376952895="&A23) -> https://docs.google.com/forms/d/e/1FAIpQLSdhNamFeglgVtt555M7xM7e8ZAg9KCWMEcDlLzX1oeZsyGxrg/viewform?usp=pp_url&entry.580385001=I-PAN-082&entry.1376952895=Pan 3125c | E23: =IFERROR(IF(C23<>"",VLOOKUP(C23,IMS!$A$2:$E1000,5,0),""),"") -> 1
A24: =IFERROR(__xludf.DUMMYFUNCTION("""COMPUTED_VALUE"""),"Pan 021c") -> Pan 021c | B24: =IFERROR(__xludf.DUMMYFUNCTION("""COMPUTED_VALUE"""),"Ink") -> Ink | C24: =IFERROR(__xludf.DUMMYFUNCTION("""COMPUTED_VALUE"""),"I-PAN-083") -> I-PAN-083 | D24: =IF(COUNTIF('Form responses 4'!B:B,C24)>0, "", "https://docs.google.com/forms/d/e/1FAIpQLSdhNamFeglgVtt555M7xM7e8ZAg9KCWMEcDlLzX1oeZsyGxrg/viewform?usp=pp_url&entry.580385001="&C24&"&entry.1376952895="&A24) -> https://docs.google.com/forms/d/e/1FAIpQLSdhNamFeglgVtt555M7xM7e8ZAg9KCWMEcDlLzX1oeZsyGxrg/viewform?usp=pp_url&entry.580385001=I-PAN-083&entry.1376952895=Pan 021c | E24: =IFERROR(IF(C24<>"",VLOOKUP(C24,IMS!$A$2:$E1000,5,0),""),"") -> 5
A25: =IFERROR(__xludf.DUMMYFUNCTION("""COMPUTED_VALUE"""),"O/S jss Orange") -> O/S jss Orange | B25: =IFERROR(__xludf.DUMMYFUNCTION("""COMPUTED_VALUE"""),"Ink") -> Ink | C25: =IFERROR(__xludf.DUMMYFUNCTION("""COMPUTED_VALUE"""),"I-PAN-084") -> I-PAN-084 | D25: =IF(COUNTIF('Form responses 4'!B:B,C25)>0, "", "https://docs.google.com/forms/d/e/1FAIpQLSdhNamFeglgVtt555M7xM7e8ZAg9KCWMEcDlLzX1oeZsyGxrg/viewform?usp=pp_url&entry.580385001="&C25&"&entry.1376952895="&A25) -> https://docs.google.com/forms/d/e/1FAIpQLSdhNamFeglgVtt555M7xM7e8ZAg9KCWMEcDlLzX1oeZsyGxrg/viewform?usp=pp_url&entry.580385001=I-PAN-084&entry.1376952895=O/S jss Orange | E25: =IFERROR(IF(C25<>"",VLOOKUP(C25,IMS!$A$2:$E1000,5,0),""),"") -> 0
A26: =IFERROR(__xludf.DUMMYFUNCTION("""COMPUTED_VALUE"""),"Biocon Red") -> Biocon Red | B26: =IFERROR(__xludf.DUMMYFUNCTION("""COMPUTED_VALUE"""),"Ink") -> Ink | C26: =IFERROR(__xludf.DUMMYFUNCTION("""COMPUTED_VALUE"""),"I-PAN-085") -> I-PAN-085 | D26: =IF(COUNTIF('Form responses 4'!B:B,C26)>0, "", "https://docs.google.com/forms/d/e/1FAIpQLSdhNamFeglgVtt555M7xM7e8ZAg9KCWMEcDlLzX1oeZsyGxrg/viewform?usp=pp_url&entry.580385001="&C26&"&entry.1376952895="&A26) -> https://docs.google.com/forms/d/e/1FAIpQLSdhNamFeglgVtt555M7xM7e8ZAg9KCWMEcDlLzX1oeZsyGxrg/viewform?usp=pp_url&entry.580385001=I-PAN-085&entry.1376952895=Biocon Red | E26: =IFERROR(IF(C26<>"",VLOOKUP(C26,IMS!$A$2:$E1000,5,0),""),"") -> 3
A27: =IFERROR(__xludf.DUMMYFUNCTION("""COMPUTED_VALUE"""),"Pan 3262c") -> Pan 3262c | B27: =IFERROR(__xludf.DUMMYFUNCTION("""COMPUTED_VALUE"""),"Ink") -> Ink | C27: =IFERROR(__xludf.DUMMYFUNCTION("""COMPUTED_VALUE"""),"I-PAN-086") -> I-PAN-086 | D27: =IF(COUNTIF('Form responses 4'!B:B,C27)>0, "", "https://docs.google.com/forms/d/e/1FAIpQLSdhNamFeglgVtt555M7xM7e8ZAg9KCWMEcDlLzX1oeZsyGxrg/viewform?usp=pp_url&entry.580385001="&C27&"&entry.1376952895="&A27) -> https://docs.google.com/forms/d/e/1FAIpQLSdhNamFeglgVtt555M7xM7e8ZAg9KCWMEcDlLzX1oeZsyGxrg/viewform?usp=pp_url&entry.580385001=I-PAN-086&entry.1376952895=Pan 3262c | E27: =IFERROR(IF(C27<>"",VLOOKUP(C27,IMS!$A$2:$E1000,5,0),""),"") -> 1
A28: =IFERROR(__xludf.DUMMYFUNCTION("""COMPUTED_VALUE"""),"Pan 188c") -> Pan 188c | B28: =IFERROR(__xludf.DUMMYFUNCTION("""COMPUTED_VALUE"""),"Ink") -> Ink | C28: =IFERROR(__xludf.DUMMYFUNCTION("""COMPUTED_VALUE"""),"I-PAN-087") -> I-PAN-087 | D28: =IF(COUNTIF('Form responses 4'!B:B,C28)>0, "", "https://docs.google.com/forms/d/e/1FAIpQLSdhNamFeglgVtt555M7xM7e8ZAg9KCWMEcDlLzX1oeZsyGxrg/viewform?usp=pp_url&entry.580385001="&C28&"&entry.1376952895="&A28) -> https://docs.google.com/forms/d/e/1FAIpQLSdhNamFeglgVtt555M7xM7e8ZAg9KCWMEcDlLzX1oeZsyGxrg/viewform?usp=pp_url&entry.580385001=I-PAN-087&entry.1376952895=Pan 188c | E28: =IFERROR(IF(C28<>"",VLOOKUP(C28,IMS!$A$2:$E1000,5,0),""),"") -> 1
A29: =IFERROR(__xludf.DUMMYFUNCTION("""COMPUTED_VALUE"""),"Pan 185c") -> Pan 185c | B29: =IFERROR(__xludf.DUMMYFUNCTION("""COMPUTED_VALUE"""),"Ink") -> Ink | C29: =IFERROR(__xludf.DUMMYFUNCTION("""COMPUTED_VALUE"""),"I-PAN-088") -> I-PAN-088 | D29: =IF(COUNTIF('Form responses 4'!B:B,C29)>0, "", "https://docs.google.com/forms/d/e/1FAIpQLSdhNamFeglgVtt555M7xM7e8ZAg9KCWMEcDlLzX1oeZsyGxrg/viewform?usp=pp_url&entry.580385001="&C29&"&entry.1376952895="&A29) -> https://docs.google.com/forms/d/e/1FAIpQLSdhNamFeglgVtt555M7xM7e8ZAg9KCWMEcDlLzX1oeZsyGxrg/viewform?usp=pp_url&entry.580385001=I-PAN-088&entry.1376952895=Pan 185c | E29: =IFERROR(IF(C29<>"",VLOOKUP(C29,IMS!$A$2:$E1000,5,0),""),"") -> 1
